<?xml version="1.0" encoding="utf-8" ?>
<!-- This URDF was automatically created by SolidWorks to URDF Exporter! Originally created by Stephen Brawner (brawner@gmail.com) 
     Commit Version: 1.6.0-4-g7f85cfe  Build Version: 1.6.7995.38578
     For more information, please see http://wiki.ros.org/sw_urdf_exporter -->
<robot name="Manipulator_URDF">
    <link name="world" />
    <joint name="base_joint" type="fixed">
        <parent link="world" />
        <child link="base_link" />
        <origin rpy="0 0 0" xyz="0.0 0.0 0.17" />
    </joint>
    <link name="base_link">
        <inertial>
            <origin xyz="0.018953 0.04778 0.068135" rpy="0 0 0" />
            <mass value="0.049053" />
            <inertia ixx="4.0047E-05" ixy="3.0608E-09" ixz="-7.9517E-09" iyy="4.1233E-05" iyz="-7.4309E-13" izz="1.5913E-05" />
        </inertial>
        <visual>
            <origin xyz="0 0 0" rpy="0 0 0" />
            <geometry>
                <mesh filename="package://Manipulator_URDF/meshes/base_link.STL" />
            </geometry>
            <material name="">
                <color rgba="0.89804 0.91765 0.92941 1" />
            </material>
        </visual>
        <collision>
            <origin xyz="0 0 0" rpy="0 0 0" />
            <geometry>
                <mesh filename="package://Manipulator_URDF/meshes/base_link.STL" />
            </geometry>
        </collision>
    </link>
    <link name="link_1">
        <inertial>
            <origin xyz="0.026643 0.067463 0.1051" rpy="0 0 0" />
            <mass value="0.053295" />
            <inertia ixx="5.0648E-06" ixy="3.7644E-08" ixz="3.9559E-09" iyy="1.0748E-05" iyz="4.0559E-07" izz="1.1407E-05" />
        </inertial>
        <visual>
            <origin xyz="0 0 0" rpy="0 0 0" />
            <geometry>
                <mesh filename="package://Manipulator_URDF/meshes/link_1.STL" />
            </geometry>
            <material name="">
                <color rgba="0.75294 0.75294 0.75294 1" />
            </material>
        </visual>
        <collision>
            <origin xyz="0 0 0" rpy="0 0 0" />
            <geometry>
                <mesh filename="package://Manipulator_URDF/meshes/link_1.STL" />
            </geometry>
        </collision>
    </link>
    <joint name="joint1" type="fixed">
        <origin xyz="0.042922 -0.17059 0.014571" rpy="1.5708 0 3.1416" />
        <parent link="base_link" />
        <child link="link_1" />
        <axis xyz="0 0 0" />
    </joint>
    <link name="link_2">
        <inertial>
            <origin xyz="-0.0093252 0.018744 0.003828" rpy="0 0 0" />
            <mass value="0.054261" />
            <inertia ixx="5.1055E-06" ixy="1.889E-08" ixz="-2.4669E-07" iyy="1.1466E-05" iyz="-4.0517E-07" izz="1.0768E-05" />
        </inertial>
        <visual>
            <origin xyz="0 0 0" rpy="0 0 0" />
            <geometry>
                <mesh filename="package://Manipulator_URDF/meshes/link_2.STL" />
            </geometry>
            <material name="">
                <color rgba="0.89804 0.91765 0.92941 1" />
            </material>
        </visual>
        <collision>
            <origin xyz="0 0 0" rpy="0 0 0" />
            <geometry>
                <mesh filename="package://Manipulator_URDF/meshes/link_2.STL" />
            </geometry>
        </collision>
    </link>
    <joint name="joint2" type="revolute">
        <origin xyz="0.016587 0.095557 0.10355" rpy="3.1416 -0.72673 3.1416" />
        <parent link="link_1" />
        <child link="link_2" />
        <axis xyz="0 1 0" />
        <limit lower="-1.57" upper="1.57" effort="200" velocity="3" />
    </joint>
    <link name="link_3">
        <inertial>
            <origin xyz="-0.0020031 0.05096 -0.0005529" rpy="0 0 0" />
            <mass value="0.047833" />
            <inertia ixx="4.6499E-05" ixy="6.4595E-07" ixz="9.3024E-07" iyy="3.0269E-05" iyz="2.3804E-08" izz="2.1291E-05" />
        </inertial>
        <visual>
            <origin xyz="0 0 0" rpy="0 0 0" />
            <geometry>
                <mesh filename="package://Manipulator_URDF/meshes/link_3.STL" />
            </geometry>
            <material name="">
                <color rgba="0.75294 0.75294 0.75294 1" />
            </material>
        </visual>
        <collision>
            <origin xyz="0 0 0" rpy="0 0 0" />
            <geometry>
                <mesh filename="package://Manipulator_URDF/meshes/link_3.STL" />
            </geometry>
        </collision>
    </link>
    <joint name="joint3" type="revolute">
        <origin xyz="-0.019387 0.0175 -0.00071444" rpy="-0.0029846 0.00012106 0.081078" />
        <parent link="link_2" />
        <child link="link_3" />
        <axis xyz="0.036827 0 -0.99932" />
        <limit lower="-1.57" upper="1.57" effort="150" velocity="3" />
    </joint>
    <link name="link_4">
        <inertial>
            <origin xyz="0.0041588 0.077415 -0.0030401" rpy="0 0 0" />
            <mass value="0.11939" />
            <inertia ixx="2.6992E-05" ixy="-5.5078E-07" ixz="-7.5265E-07" iyy="1.1445E-05" iyz="1.0514E-08" izz="2.5362E-05" />
        </inertial>
        <visual>
            <origin xyz="0 0 0" rpy="0 0 0" />
            <geometry>
                <mesh filename="package://Manipulator_URDF/meshes/link_4.STL" />
            </geometry>
            <material name="">
                <color rgba="0.89804 0.91765 0.92941 1" />
            </material>
        </visual>
        <collision>
            <origin xyz="0 0 0" rpy="0 0 0" />
            <geometry>
                <mesh filename="package://Manipulator_URDF/meshes/link_4.STL" />
            </geometry>
        </collision>
    </link>
    <joint name="joint4" type="revolute">
        <origin xyz="-0.0040415 0.10192 -0.00014894" rpy="-0.0013244 2.3807E-05 0.035947" />
        <parent link="link_3" />
        <child link="link_4" />
        <axis xyz="0.036827 0 -0.99932" />
        <limit lower="-1.57" upper="1.57" effort="100" velocity="3" />
        <mimic joint="joint2" multiplier="1" offset="0" />
    </joint>
    <link name="link_5">
        <inertial>
            <origin xyz="0.0029647 0.03703 2.0924E-06" rpy="0 0 0" />
            <mass value="0.050955" />
            <inertia ixx="2.6187E-05" ixy="-4.8287E-07" ixz="5.8904E-07" iyy="2.0198E-05" iyz="2.1584E-08" izz="1.031E-05" />
        </inertial>
        <visual>
            <origin xyz="0 0 0" rpy="0 0 0" />
            <geometry>
                <mesh filename="package://Manipulator_URDF/meshes/link_5.STL" />
            </geometry>
            <material name="">
                <color rgba="0.75294 0.75294 0.75294 1" />
            </material>
        </visual>
        <collision>
            <origin xyz="0 0 0" rpy="0 0 0" />
            <geometry>
                <mesh filename="package://Manipulator_URDF/meshes/link_5.STL" />
            </geometry>
        </collision>
    </link>
    <joint name="joint5" type="revolute">
        <origin xyz="0.0052034 0.14577 0.00019176" rpy="0.00059508 0 -0.016149" />
        <parent link="link_4" />
        <child link="link_5" />
        <axis xyz="0.036827 0 -0.99932" />
        <limit lower="-1.57" upper="1.57" effort="80" velocity="3" />
    </joint>
    <link name="link_6">
        <inertial>
            <origin xyz="0.0029085 0.030963 0.027631" rpy="0 0 0" />
            <mass value="0.036481" />
            <inertia ixx="5.1526E-06" ixy="8.4505E-08" ixz="2.4174E-06" iyy="6.3867E-06" iyz="-1.7952E-07" izz="4.2754E-06" />
        </inertial>
        <visual>
            <origin xyz="0 0 0" rpy="0 0 0" />
            <geometry>
                <mesh filename="package://Manipulator_URDF/meshes/link_6.STL" />
            </geometry>
            <material name="">
                <color rgba="0.89804 0.91765 0.92941 1" />
            </material>
        </visual>
        <collision>
            <origin xyz="0 0 0" rpy="0 0 0" />
            <geometry>
                <mesh filename="package://Manipulator_URDF/meshes/link_6.STL" />
            </geometry>
        </collision>
    </link>
    <joint name="joint6" type="revolute">
        <origin xyz="0.0056933 0.066372 -0.010197" rpy="3.0762 0.63346 2.9605" />
        <parent link="link_5" />
        <child link="link_6" />
        <axis xyz="0.079753 0.99681 0.002939" />
        <limit lower="-1.57" upper="1.57" effort="50" velocity="3" />
    </joint>
    <link name="link_7">
        <inertial>
            <origin xyz="-0.0045079 0.0038712 -0.0014506" rpy="0 0 0" />
            <mass value="0.0023389" />
            <inertia ixx="2.7138E-07" ixy="3.9294E-08" ixz="5.8021E-08" iyy="1.2298E-07" iyz="-6.3983E-08" izz="2.4532E-07" />
        </inertial>
        <visual>
            <origin xyz="0 0 0" rpy="0 0 0" />
            <geometry>
                <mesh filename="package://Manipulator_URDF/meshes/link_7.STL" />
            </geometry>
            <material name="">
                <color rgba="0.75294 0.75294 0.75294 1" />
            </material>
        </visual>
        <collision>
            <origin xyz="0 0 0" rpy="0 0 0" />
            <geometry>
                <mesh filename="package://Manipulator_URDF/meshes/link_7.STL" />
            </geometry>
        </collision>
    </link>
    <joint name="joint7" type="revolute">
        <origin xyz="-0.0062233 0.032836 0.010313" rpy="-1.0659 -0.43408 -0.88021" />
        <parent link="link_6" />
        <child link="link_7" />
        <axis xyz="0.75436 -0.062282 0.6535" />
        <limit lower="-1.57" upper="1.57" effort="50" velocity="3" />
    </joint>
    <!--  <link
    name="link_End">
    <inertial>
      <origin
        xyz="-0.0062734 0.50916 0.10978"
        rpy="0 0 0" />
      <mass
        value="0.0029678" />
      <inertia
        ixx="8.7553E-07"
        ixy="-1.6854E-07"
        ixz="3.7411E-08"
        iyy="8.3038E-08"
        iyz="1.146E-07"
        izz="8.8959E-07" />
    </inertial>
    <visual>
      <origin
        xyz="0 0 0"
        rpy="0 0 0" />
      <geometry>
        <mesh
          filename="package://Manipulator_URDF/meshes/link_End.STL" />
      </geometry>
      <material
        name="">
        <color
          rgba="0.89804 0.91765 0.92941 1" />
      </material>
    </visual>
    <collision>
      <origin
        xyz="0 0 0"
        rpy="0 0 0" />
      <geometry>
        <mesh
          filename="package://Manipulator_URDF/meshes/link_End.STL" />
      </geometry>
    </collision>
  </link>
  <joint
    name="jointEnd"
    type="floating">
    <origin
      xyz="0.29055 0.044276 -0.38783"
      rpy="0.94013 -0.49562 0.75936" />
    <parent
      link="link_7" />
    <child
      link="link_End" />
    <axis
      xyz="0 0 0" />
  </joint>
   <link
    name="link_7_2">
    <inertial>
      <origin
        xyz="0.0031121 -0.014499 -0.0079965"
        rpy="0 0 0" />
      <mass
        value="0.0003125" />
      <inertia
        ixx="3.58E-08"
        ixy="9.2234E-09"
        ixz="4.2656E-09"
        iyy="9.3477E-09"
        iyz="-1.3448E-08"
        izz="3.2528E-08" />
    </inertial>
    <visual>
      <origin
        xyz="0 0 0"
        rpy="0 0 0" />
      <geometry>
        <mesh
          filename="package://Manipulator_URDF/meshes/link_7_2.STL" />
      </geometry>
      <material
        name="">
        <color
          rgba="0.75294 0.75294 0.75294 1" />
      </material>
    </visual>
    <collision>
      <origin
        xyz="0 0 0"
        rpy="0 0 0" />
      <geometry>
        <mesh
          filename="package://Manipulator_URDF/meshes/link_7_2.STL" />
      </geometry>
    </collision>
  </link>
  <joint
    name="joint7_2"
    type="continuous">
    <origin
      xyz="0.0015619 0.052298 0.0031813"
      rpy="1.0457 -0.60353 0.82564" />
    <parent
      link="link_6" />
    <child
      link="link_7_2" />
    <axis
      xyz="0.75436 -0.062282 0.6535" />
    <limit
      lower="-1.57"
      upper="0"
      effort="0"
      velocity="0" />
  </joint>
  <link
    name="link_End_2">
    <inertial>
      <origin
        xyz="-0.00627338291742126 0.509155967160998 0.109782863971423"
        rpy="0 0 0" />
      <mass
        value="0.00296780654025875" />
      <inertia
        ixx="8.75530948162945E-07"
        ixy="-1.68535998316117E-07"
        ixz="3.7411174170203E-08"
        iyy="8.30383875085134E-08"
        iyz="1.14604664997385E-07"
        izz="8.89591952373185E-07" />
    </inertial>
    <visual>
      <origin
        xyz="0 0 0"
        rpy="0 0 0" />
      <geometry>
        <mesh
          filename="package://Manipulator_URDF/meshes/link_End_2.STL" />
      </geometry>
      <material
        name="">
        <color
          rgba="0.752941176470588 0.752941176470588 0.752941176470588 1" />
      </material>
    </visual>
    <collision>
      <origin
        xyz="0 0 0"
        rpy="0 0 0" />
      <geometry>
        <mesh
          filename="package://Manipulator_URDF/meshes/link_End_2.STL" />
      </geometry>
    </collision>
  </link>
  <joint
    name="jointEnd_2"
    type="floating">
    <origin
      xyz="-0.35851 -0.026569 0.35465"
      rpy="-1.1727 -0.53818 -0.95177" />
    <parent
      link="link_7_2" />
    <child
      link="link_End_2" />
    <axis
      xyz="0 0 0" />
  </joint> -->
    <transmission name="link_1_trans">
        <type>transmission_interface/SimpleTransmission</type>
        <joint name="joint1">
            <hardwareInterface>hardware_interface/PositionJointInterface</hardwareInterface>
        </joint>
        <actuator name="link_1_motor">
            <hardwareInterface>hardware_interface/PositionJointInterface</hardwareInterface>
            <mechanicalReduction>1</mechanicalReduction>
        </actuator>
    </transmission>
    <transmission name="link_2_trans">
        <type>transmission_interface/SimpleTransmission</type>
        <joint name="joint2">
            <hardwareInterface>hardware_interface/PositionJointInterface</hardwareInterface>
        </joint>
        <actuator name="link_2_motor">
            <hardwareInterface>hardware_interface/PositionJointInterface</hardwareInterface>
            <mechanicalReduction>1</mechanicalReduction>
        </actuator>
    </transmission>
    <transmission name="link_3_trans">
        <type>transmission_interface/SimpleTransmission</type>
        <joint name="joint3">
            <hardwareInterface>hardware_interface/PositionJointInterface</hardwareInterface>
        </joint>
        <actuator name="link_3_motor">
            <hardwareInterface>hardware_interface/PositionJointInterface</hardwareInterface>
            <mechanicalReduction>1</mechanicalReduction>
        </actuator>
    </transmission>
    <transmission name="link_4_trans">
        <type>transmission_interface/SimpleTransmission</type>
        <joint name="joint4">
            <hardwareInterface>hardware_interface/PositionJointInterface</hardwareInterface>
        </joint>
        <actuator name="link_4_motor">
            <hardwareInterface>hardware_interface/PositionJointInterface</hardwareInterface>
            <mechanicalReduction>1</mechanicalReduction>
        </actuator>
    </transmission>
    <transmission name="link_5_trans">
        <type>transmission_interface/SimpleTransmission</type>
        <joint name="joint5">
            <hardwareInterface>hardware_interface/PositionJointInterface</hardwareInterface>
        </joint>
        <actuator name="link_5_motor">
            <hardwareInterface>hardware_interface/PositionJointInterface</hardwareInterface>
            <mechanicalReduction>1</mechanicalReduction>
        </actuator>
    </transmission>
    <transmission name="link_6_trans">
        <type>transmission_interface/SimpleTransmission</type>
        <joint name="joint6">
            <hardwareInterface>hardware_interface/PositionJointInterface</hardwareInterface>
        </joint>
        <actuator name="link_6_motor">
            <hardwareInterface>hardware_interface/PositionJointInterface</hardwareInterface>
            <mechanicalReduction>1</mechanicalReduction>
        </actuator>
    </transmission>
    <transmission name="link_7_trans">
        <type>transmission_interface/SimpleTransmission</type>
        <joint name="joint7">
            <hardwareInterface>hardware_interface/PositionJointInterface</hardwareInterface>
        </joint>
        <actuator name="link_7_motor">
            <hardwareInterface>hardware_interface/PositionJointInterface</hardwareInterface>
            <mechanicalReduction>1</mechanicalReduction>
        </actuator>
    </transmission>
    <gazebo>
        <plugin name="control" filename="libgazebo_ros_control.so">
            <robotNamespace>/</robotNamespace>
        </plugin>
        <plugin name="gazebo_ros_control">
            <robotNamespace>/</robotNamespace>
        </plugin>
    </gazebo>
    <gazebo reference="link_1">
        <selfCollide>true</selfCollide>
    </gazebo>
    <gazebo reference="link_2">
        <selfCollide>true</selfCollide>
    </gazebo>
    <gazebo reference="link_3">
        <selfCollide>true</selfCollide>
    </gazebo>
    <gazebo reference="link_4">
        <selfCollide>true</selfCollide>
    </gazebo>
    <gazebo reference="link_5">
        <selfCollide>true</selfCollide>
    </gazebo>
    <gazebo reference="link_6">
        <selfCollide>true</selfCollide>
    </gazebo>
    <gazebo reference="link_7">
        <selfCollide>true</selfCollide>
    </gazebo>
    <!-- <gazebo reference="link_7_2">
    <selfCollide>true</selfCollide>
  </gazebo>
  <gazebo reference="link_End_2">
    <selfCollide>true</selfCollide>
  </gazebo> -->
</robot>

